Workbook
Name Slicer_churn: #N/A
Name Slicer_international_plan: #N/A
Name Slicer_Tenure_Group: #N/A
Name Slicer_voice_mail_plan: #N/A

Sheet Dashboard
A1: Telecommunications Churn Quest
A2: Sum Of Churn | C2: Average Churn Rate | E2: Sum of Day charges | G2: Sum of Evening charges | I2: Sum of Night charges | K2: Sum of International charges
A5: =GETPIVOTDATA("churn_numeric",'Reference Pivot Table'!$A$3) -> 598 | C5: =GETPIVOTDATA("churn_numeric",'Reference Pivot Table'!$A$9) -> 0.14070588 | E5: =GETPIVOTDATA("Sum of total_day_charge",'Reference Pivot Table'!$A$47) -> 130239.9 | G5: =GETPIVOTDATA("Sum of total_eve_charge",'Reference Pivot Table'!$A$47) -> 72313.8 | I5: =GETPIVOTDATA("Sum of total_night_charge",'Reference Pivot Table'!$A$47) -> 38351.54 | K5: =GETPIVOTDATA("Sum of total_intl_charge",'Reference Pivot Table'!$A$47) -> 11771.03

Sheet Reference Pivot Table
A3: Sum of churn_numeric | F3: Area Code | G3: Count of churn
A4: 598 | F4: area_code_408 | G4: 0.25552941
F5: area_code_415 | G5: 0.496
A6: Count of churn_numeric | F6: area_code_510 | G6: 0.24847059
A7: 4250 | F7: Grand Total | G7: 1
A9: Average of churn_numeric | F9: Count of churn | G9: Column Labels
A10: 0.14070588 | F10: Customer service calls | G10: no | H10: yes | I10: Grand Total
F11: 4 | G11: 0.70909091 | H11: 0.54117647 | I11: 0.6238806
A12: Churn | B12: Sum of account_length | F12: 5 | G12: 0.19393939 | H12: 0.28823529 | I12: 0.24179104
A13: no | B13: 364926 | F13: 6 | G13: 0.054545455 | H13: 0.11176471 | I13: 0.08358209
A14: yes | B14: 61078 | F14: 7 | G14: 0.036363636 | H14: 0.041176471 | I14: 0.03880597
A15: Grand Total | B15: 426004 | F15: 8 | G15: 0.0060606061 | H15: 0.0058823529 | I15: 0.0059701493
F16: 9 | G16: 0 | H16: 0.011764706 | I16: 0.0059701493
A17: Churn | B17: Count of international_plan | F17: Grand Total | G17: 1 | H17: 1 | I17: 1
A18: no | B18: 3652
A19: yes | B19: 598 | F19: Row Labels | G19: Sum of churn_Numeric
A20: Grand Total | B20: 4250 | F20: High Day & Eve | G20: 173
F21: High Day Only | G21: 199
A22: Churn | B22: Sum of number_customer_service_calls | F22: High Eve Only | G22: 116
A23: no | B23: 5265 | F23: Low Usage | G23: 110
A24: yes | B24: 1361 | F24: Grand Total | G24: 598
A25: Grand Total | B25: 6626
A27: Churn | B27: Sum of total_day_minutes | F27: Count of churn | G27: Column Labels
A28: no | B28: 641127.2 | F28: Row Labels | G28: no | H28: yes | I28: Grand Total
A29: yes | B29: 124976.1 | F29: High | G29: 0.24123768 | H29: 0.27759197 | I29: 0.24635294
A30: Grand Total | B30: 766103.3 | F30: Low | G30: 0.25794085 | H30: 0.23076923 | I30: 0.25411765
F31: Medium | G31: 0.25547645 | H31: 0.26086957 | I31: 0.25623529
A32: Churn | B32: Sum of vm_plan_num | F32: Very High | G32: 0.24534502 | H32: 0.23076923 | I32: 0.24329412
A33: no | B33: 1030 | F33: Grand Total | G33: 1 | H33: 1 | I33: 1
A34: yes | B34: 82
A35: Grand Total | B35: 1112
A37: Churn | B37: Sum of total_intl_minutes | F37: . | G37: Churn
A38: no | B38: 37230.1 | F38: charges | G38: no | H38: yes | I38: Grand Total
A39: yes | B39: 6358.2 | F39: High | G39: 0.5060241 | H39: 0.55518395 | I39: 0.51294118
A40: Grand Total | B40: 43588.3 | F40: Low | G40: 0.4939759 | H40: 0.44481605 | I40: 0.48705882
F41: Grand Total | G41: 1 | H41: 1 | I41: 1
A42: Churn | B42: Sum of total_eve_charge
A43: no | B43: 61641.17
A44: yes | B44: 10672.63
A45: Grand Total | B45: 72313.8
...

Sheet train
A1: state | B1: account_length | C1: area_code | D1: international_plan | E1: voice_mail_plan | F1: number_vmail_messages | G1: total_day_minutes | H1: total_day_calls | I1: total_day_charge | J1: total_eve_minutes | K1: total_eve_calls | L1: total_eve_charge | M1: total_night_minutes | N1: total_night_calls | O1: total_night_charge | P1: total_intl_minutes | Q1: total_intl_calls | R1: total_intl_charge | S1: number_customer_service_calls | T1: churn | U1: churn_Numeric | V1: Intl_Plan_num | W1: Vm_plan_num | X1: Tenure | Y1: High/Low_intl_charges | Z1: Usage_Level | AC1: Tenure Reference
A2: OH | B2: 107 | C2: area_code_415 | D2: no | E2: yes | F2: 26 | G2: 161.6 | H2: 123 | I2: 27.47 | J2: 195.5 | K2: 103 | L2: 16.62 | M2: 254.4 | N2: 103 | O2: 11.45 | P2: 13.7 | Q2: 3 | R2: 3.7 | S2: 1 | T2: no | U2: =IF(T2="yes",1,0) -> 0 | V2: =IF(Table2[[#This Row],[international_plan]]="yes",1,0) -> 0 | W2: =IF(Table2[[#This Row],[voice_mail_plan]]="yes",1,0) -> 1 | X2: =IF(B2<=$AC$3,"Low",IF(B2<=$AC$4,"Medium",IF(B2<=$AC$5,"High",IF(B2>=$AC$5,"Very High")))) -> High | Y2: =IF(Table2[[#This Row],[total_intl_charge]] > AVERAGE($R$2:$R$4245),"High","Low") -> High | Z2: =IF(AND(G2>AVERAGE(train!$G$2:$G$4251),K2>AVERAGE(train!$K$2:$K$4251)),"High Day & Eve",IF(AND(G2>AVERAGE(train!$G$2:$G$4251),K2<=AVERAGE(train!$K$2:$K$4251)),"High Day Only",IF(AND(G2<=AVERAGE(train!$G$2:$G$4251),K2>AVERAGE(train!$K$2:$K$4251)),"High Eve Only","Low Usage"))) -> High Eve Only | AC2: =QUARTILE($B$2:$B$1000,0) -> 1
A3: NJ | B3: 137 | C3: area_code_415 | D3: no | E3: no | F3: 0 | G3: 243.4 | H3: 114 | I3: 41.38 | J3: 121.2 | K3: 110 | L3: 10.3 | M3: 162.6 | N3: 104 | O3: 7.32 | P3: 12.2 | Q3: 5 | R3: 3.29 | S3: 0 | T3: no | U3: =IF(T3="yes",1,0) -> 0 | V3: =IF(Table2[[#This Row],[international_plan]]="yes",1,0) -> 0 | W3: =IF(Table2[[#This Row],[voice_mail_plan]]="yes",1,0) -> 0 | X3: =IF(B3<=$AC$3,"Low",IF(B3<=$AC$4,"Medium",IF(B3<=$AC$5,"High",IF(B3>=$AC$5,"Very High")))) -> Very High | Y3: =IF(Table2[[#This Row],[total_intl_charge]] > AVERAGE($R$2:$R$4245),"High","Low") -> High | Z3: =IF(AND(G3>AVERAGE(train!$G$2:$G$4251),K3>AVERAGE(train!$K$2:$K$4251)),"High Day & Eve",IF(AND(G3>AVERAGE(train!$G$2:$G$4251),K3<=AVERAGE(train!$K$2:$K$4251)),"High Day Only",IF(AND(G3<=AVERAGE(train!$G$2:$G$4251),K3>AVERAGE(train!$K$2:$K$4251)),"High Eve Only","Low Usage"))) -> High Day & Eve | AC3: =QUARTILE($B$2:$B$4251,1) -> 73
A4: OH | B4: 84 | C4: area_code_408 | D4: yes | E4: no | F4: 0 | G4: 299.4 | H4: 71 | I4: 50.9 | J4: 61.9 | K4: 88 | L4: 5.26 | M4: 196.9 | N4: 89 | O4: 8.86 | P4: 6.6 | Q4: 7 | R4: 1.78 | S4: 2 | T4: no | U4: =IF(T4="yes",1,0) -> 0 | V4: =IF(Table2[[#This Row],[international_plan]]="yes",1,0) -> 1 | W4: =IF(Table2[[#This Row],[voice_mail_plan]]="yes",1,0) -> 0 | X4: =IF(B4<=$AC$3,"Low",IF(B4<=$AC$4,"Medium",IF(B4<=$AC$5,"High",IF(B4>=$AC$5,"Very High")))) -> Medium | Y4: =IF(Table2[[#This Row],[total_intl_charge]] > AVERAGE($R$2:$R$4245),"High","Low") -> Low | Z4: =IF(AND(G4>AVERAGE(train!$G$2:$G$4251),K4>AVERAGE(train!$K$2:$K$4251)),"High Day & Eve",IF(AND(G4>AVERAGE(train!$G$2:$G$4251),K4<=AVERAGE(train!$K$2:$K$4251)),"High Day Only",IF(AND(G4<=AVERAGE(train!$G$2:$G$4251),K4>AVERAGE(train!$K$2:$K$4251)),"High Eve Only","Low Usage"))) -> High Day Only | AC4: =QUARTILE($B$2:$B$4251,2) -> 100
A5: OK | B5: 75 | C5: area_code_415 | D5: yes | E5: no | F5: 0 | G5: 166.7 | H5: 113 | I5: 28.34 | J5: 148.3 | K5: 122 | L5: 12.61 | M5: 186.9 | N5: 121 | O5: 8.41 | P5: 10.1 | Q5: 3 | R5: 2.73 | S5: 3 | T5: no | U5: =IF(T5="yes",1,0) -> 0 | V5: =IF(Table2[[#This Row],[international_plan]]="yes",1,0) -> 1 | W5: =IF(Table2[[#This Row],[voice_mail_plan]]="yes",1,0) -> 0 | X5: =IF(B5<=$AC$3,"Low",IF(B5<=$AC$4,"Medium",IF(B5<=$AC$5,"High",IF(B5>=$AC$5,"Very High")))) -> Medium | Y5: =IF(Table2[[#This Row],[total_intl_charge]] > AVERAGE($R$2:$R$4245),"High","Low") -> Low | Z5: =IF(AND(G5>AVERAGE(train!$G$2:$G$4251),K5>AVERAGE(train!$K$2:$K$4251)),"High Day & Eve",IF(AND(G5>AVERAGE(train!$G$2:$G$4251),K5<=AVERAGE(train!$K$2:$K$4251)),"High Day Only",IF(AND(G5<=AVERAGE(train!$G$2:$G$4251),K5>AVERAGE(train!$K$2:$K$4251)),"High Eve Only","Low Usage"))) -> High Eve Only | AC5: =QUARTILE($B$2:$B$4251,3) -> 127
A6: MA | B6: 121 | C6: area_code_510 | D6: no | E6: yes | F6: 24 | G6: 218.2 | H6: 88 | I6: 37.09 | J6: 348.5 | K6: 108 | L6: 29.62 | M6: 212.6 | N6: 118 | O6: 9.57 | P6: 7.5 | Q6: 7 | R6: 2.03 | S6: 3 | T6: no | U6: =IF(T6="yes",1,0) -> 0 | V6: =IF(Table2[[#This Row],[international_plan]]="yes",1,0) -> 0 | W6: =IF(Table2[[#This Row],[voice_mail_plan]]="yes",1,0) -> 1 | X6: =IF(B6<=$AC$3,"Low",IF(B6<=$AC$4,"Medium",IF(B6<=$AC$5,"High",IF(B6>=$AC$5,"Very High")))) -> High | Y6: =IF(Table2[[#This Row],[total_intl_charge]] > AVERAGE($R$2:$R$4245),"High","Low") -> Low | Z6: =IF(AND(G6>AVERAGE(train!$G$2:$G$4251),K6>AVERAGE(train!$K$2:$K$4251)),"High Day & Eve",IF(AND(G6>AVERAGE(train!$G$2:$G$4251),K6<=AVERAGE(train!$K$2:$K$4251)),"High Day Only",IF(AND(G6<=AVERAGE(train!$G$2:$G$4251),K6>AVERAGE(train!$K$2:$K$4251)),"High Eve Only","Low Usage"))) -> High Day & Eve | AC6: =QUARTILE($B$2:$B$1000,4) -> 243
A7: MO | B7: 147 | C7: area_code_415 | D7: yes | E7: no | F7: 0 | G7: 157 | H7: 79 | I7: 26.69 | J7: 103.1 | K7: 94 | L7: 8.76 | M7: 211.8 | N7: 96 | O7: 9.53 | P7: 7.1 | Q7: 6 | R7: 1.92 | S7: 0 | T7: no | U7: =IF(T7="yes",1,0) -> 0 | V7: =IF(Table2[[#This Row],[international_plan]]="yes",1,0) -> 1 | W7: =IF(Table2[[#This Row],[voice_mail_plan]]="yes",1,0) -> 0 | X7: =IF(B7<=$AC$3,"Low",IF(B7<=$AC$4,"Medium",IF(B7<=$AC$5,"High",IF(B7>=$AC$5,"Very High")))) -> Very High | Y7: =IF(Table2[[#This Row],[total_intl_charge]] > AVERAGE($R$2:$R$4245),"High","Low") -> Low | Z7: =IF(AND(G7>AVERAGE(train!$G$2:$G$4251),K7>AVERAGE(train!$K$2:$K$4251)),"High Day & Eve",IF(AND(G7>AVERAGE(train!$G$2:$G$4251),K7<=AVERAGE(train!$K$2:$K$4251)),"High Day Only",IF(AND(G7<=AVERAGE(train!$G$2:$G$4251),K7>AVERAGE(train!$K$2:$K$4251)),"High Eve Only","Low Usage"))) -> Low Usage
A8: LA | B8: 117 | C8: area_code_408 | D8: no | E8: no | F8: 0 | G8: 184.5 | H8: 97 | I8: 31.37 | J8: 351.6 | K8: 80 | L8: 29.89 | M8: 215.8 | N8: 90 | O8: 9.71 | P8: 8.7 | Q8: 4 | R8: 2.35 | S8: 1 | T8: no | U8: =IF(T8="yes",1,0) -> 0 | V8: =IF(Table2[[#This Row],[international_plan]]="yes",1,0) -> 0 | W8: =IF(Table2[[#This Row],[voice_mail_plan]]="yes",1,0) -> 0 | X8: =IF(B8<=$AC$3,"Low",IF(B8<=$AC$4,"Medium",IF(B8<=$AC$5,"High",IF(B8>=$AC$5,"Very High")))) -> High | Y8: =IF(Table2[[#This Row],[total_intl_charge]] > AVERAGE($R$2:$R$4245),"High","Low") -> Low | Z8: =IF(AND(G8>AVERAGE(train!$G$2:$G$4251),K8>AVERAGE(train!$K$2:$K$4251)),"High Day & Eve",IF(AND(G8>AVERAGE(train!$G$2:$G$4251),K8<=AVERAGE(train!$K$2:$K$4251)),"High Day Only",IF(AND(G8<=AVERAGE(train!$G$2:$G$4251),K8>AVERAGE(train!$K$2:$K$4251)),"High Eve Only","Low Usage"))) -> High Day Only
A9: WV | B9: 141 | C9: area_code_415 | D9: yes | E9: yes | F9: 37 | G9: 258.6 | H9: 84 | I9: 43.96 | J9: 222 | K9: 111 | L9: 18.87 | M9: 326.4 | N9: 97 | O9: 14.69 | P9: 11.2 | Q9: 5 | R9: 3.02 | S9: 0 | T9: no | U9: =IF(T9="yes",1,0) -> 0 | V9: =IF(Table2[[#This Row],[international_plan]]="yes",1,0) -> 1 | W9: =IF(Table2[[#This Row],[voice_mail_plan]]="yes",1,0) -> 1 | X9: =IF(B9<=$AC$3,"Low",IF(B9<=$AC$4,"Medium",IF(B9<=$AC$5,"High",IF(B9>=$AC$5,"Very High")))) -> Very High | Y9: =IF(Table2[[#This Row],[total_intl_charge]] > AVERAGE($R$2:$R$4245),"High","Low") -> High | Z9: =IF(AND(G9>AVERAGE(train!$G$2:$G$4251),K9>AVERAGE(train!$K$2:$K$4251)),"High Day & Eve",IF(AND(G9>AVERAGE(train!$G$2:$G$4251),K9<=AVERAGE(train!$K$2:$K$4251)),"High Day Only",IF(AND(G9<=AVERAGE(train!$G$2:$G$4251),K9>AVERAGE(train!$K$2:$K$4251)),"High Eve Only","Low Usage"))) -> High Day & Eve
A10: IN | B10: 65 | C10: area_code_415 | D10: no | E10: no | F10: 0 | G10: 129.1 | H10: 137 | I10: 21.95 | J10: 228.5 | K10: 83 | L10: 19.42 | M10: 208.8 | N10: 111 | O10: 9.4 | P10: 12.7 | Q10: 6 | R10: 3.43 | S10: 4 | T10: yes | U10: =IF(T10="yes",1,0) -> 1 | V10: =IF(Table2[[#This Row],[international_plan]]="yes",1,0) -> 0 | W10: =IF(Table2[[#This Row],[voice_mail_plan]]="yes",1,0) -> 0 | X10: =IF(B10<=$AC$3,"Low",IF(B10<=$AC$4,"Medium",IF(B10<=$AC$5,"High",IF(B10>=$AC$5,"Very High")))) -> Low | Y10: =IF(Table2[[#This Row],[total_intl_charge]] > AVERAGE($R$2:$R$4245),"High","Low") -> High | Z10: =IF(AND(G10>AVERAGE(train!$G$2:$G$4251),K10>AVERAGE(train!$K$2:$K$4251)),"High Day & Eve",IF(AND(G10>AVERAGE(train!$G$2:$G$4251),K10<=AVERAGE(train!$K$2:$K$4251)),"High Day Only",IF(AND(G10<=AVERAGE(train!$G$2:$G$4251),K10>AVERAGE(train!$K$2:$K$4251)),"High Eve Only","Low Usage"))) -> Low Usage
A11: RI | B11: 74 | C11: area_code_415 | D11: no | E11: no | F11: 0 | G11: 187.7 | H11: 127 | I11: 31.91 | J11: 163.4 | K11: 148 | L11: 13.89 | M11: 196 | N11: 94 | O11: 8.82 | P11: 9.1 | Q11: 5 | R11: 2.46 | S11: 0 | T11: no | U11: =IF(T11="yes",1,0) -> 0 | V11: =IF(Table2[[#This Row],[international_plan]]="yes",1,0) -> 0 | W11: =IF(Table2[[#This Row],[voice_mail_plan]]="yes",1,0) -> 0 | X11: =IF(B11<=$AC$3,"Low",IF(B11<=$AC$4,"Medium",IF(B11<=$AC$5,"High",IF(B11>=$AC$5,"Very High")))) -> Medium | Y11: =IF(Table2[[#This Row],[total_intl_charge]] > AVERAGE($R$2:$R$4245),"High","Low") -> Low | Z11: =IF(AND(G11>AVERAGE(train!$G$2:$G$4251),K11>AVERAGE(train!$K$2:$K$4251)),"High Day & Eve",IF(AND(G11>AVERAGE(train!$G$2:$G$4251),K11<=AVERAGE(train!$K$2:$K$4251)),"High Day Only",IF(AND(G11<=AVERAGE(train!$G$2:$G$4251),K11>AVERAGE(train!$K$2:$K$4251)),"High Eve Only","Low Usage"))) -> High Day & Eve
A12: IA | B12: 168 | C12: area_code_408 | D12: no | E12: no | F12: 0 | G12: 128.8 | H12: 96 | I12: 21.9 | J12: 104.9 | K12: 71 | L12: 8.92 | M12: 141.1 | N12: 128 | O12: 6.35 | P12: 11.2 | Q12: 2 | R12: 3.02 | S12: 1 | T12: no | U12: =IF(T12="yes",1,0) -> 0 | V12: =IF(Table2[[#This Row],[international_plan]]="yes",1,0) -> 0 | W12: =IF(Table2[[#This Row],[voice_mail_plan]]="yes",1,0) -> 0 | X12: =IF(B12<=$AC$3,"Low",IF(B12<=$AC$4,"Medium",IF(B12<=$AC$5,"High",IF(B12>=$AC$5,"Very High")))) -> Very High | Y12: =IF(Table2[[#This Row],[total_intl_charge]] > AVERAGE($R$2:$R$4245),"High","Low") -> High | Z12: =IF(AND(G12>AVERAGE(train!$G$2:$G$4251),K12>AVERAGE(train!$K$2:$K$4251)),"High Day & Eve",IF(AND(G12>AVERAGE(train!$G$2:$G$4251),K12<=AVERAGE(train!$K$2:$K$4251)),"High Day Only",IF(AND(G12<=AVERAGE(train!$G$2:$G$4251),K12>AVERAGE(train!$K$2:$K$4251)),"High Eve Only","Low Usage"))) -> Low Usage
A13: MT | B13: 95 | C13: area_code_510 | D13: no | E13: no | F13: 0 | G13: 156.6 | H13: 88 | I13: 26.62 | J13: 247.6 | K13: 75 | L13: 21.05 | M13: 192.3 | N13: 115 | O13: 8.65 | P13: 12.3 | Q13: 5 | R13: 3.32 | S13: 3 | T13: no | U13: =IF(T13="yes",1,0) -> 0 | V13: =IF(Table2[[#This Row],[international_plan]]="yes",1,0) -> 0 | W13: =IF(Table2[[#This Row],[voice_mail_plan]]="yes",1,0) -> 0 | X13: =IF(B13<=$AC$3,"Low",IF(B13<=$AC$4,"Medium",IF(B13<=$AC$5,"High",IF(B13>=$AC$5,"Very High")))) -> Medium | Y13: =IF(Table2[[#This Row],[total_intl_charge]] > AVERAGE($R$2:$R$4245),"High","Low") -> High | Z13: =IF(AND(G13>AVERAGE(train!$G$2:$G$4251),K13>AVERAGE(train!$K$2:$K$4251)),"High Day & Eve",IF(AND(G13>AVERAGE(train!$G$2:$G$4251),K13<=AVERAGE(train!$K$2:$K$4251)),"High Day Only",IF(AND(G13<=AVERAGE(train!$G$2:$G$4251),K13>AVERAGE(train!$K$2:$K$4251)),"High Eve Only","Low Usage"))) -> Low Usage
A14: NY | B14: 161 | C14: area_code_415 | D14: no | E14: no | F14: 0 | G14: 332.9 | H14: 67 | I14: 56.59 | J14: 317.8 | K14: 97 | L14: 27.01 | M14: 160.6 | N14: 128 | O14: 7.23 | P14: 5.4 | Q14: 9 | R14: 1.46 | S14: 4 | T14: yes | U14: =IF(T14="yes",1,0) -> 1 | V14: =IF(Table2[[#This Row],[international_plan]]="yes",1,0) -> 0 | W14: =IF(Table2[[#This Row],[voice_mail_plan]]="yes",1,0) -> 0 | X14: =IF(B14<=$AC$3,"Low",IF(B14<=$AC$4,"Medium",IF(B14<=$AC$5,"High",IF(B14>=$AC$5,"Very High")))) -> Very High | Y14: =IF(Table2[[#This Row],[total_intl_charge]] > AVERAGE($R$2:$R$4245),"High","Low") -> Low | Z14: =IF(AND(G14>AVERAGE(train!$G$2:$G$4251),K14>AVERAGE(train!$K$2:$K$4251)),"High Day & Eve",IF(AND(G14>AVERAGE(train!$G$2:$G$4251),K14<=AVERAGE(train!$K$2:$K$4251)),"High Day Only",IF(AND(G14<=AVERAGE(train!$G$2:$G$4251),K14>AVERAGE(train!$K$2:$K$4251)),"High Eve Only","Low Usage"))) -> High Day Only
A15: ID | B15: 85 | C15: area_code_408 | D15: no | E15: yes | F15: 27 | G15: 196.4 | H15: 139 | I15: 33.39 | J15: 280.9 | K15: 90 | L15: 23.88 | M15: 89.3 | N15: 75 | O15: 4.02 | P15: 13.8 | Q15: 4 | R15: 3.73 | S15: 1 | T15: no | U15: =IF(T15="yes",1,0) -> 0 | V15: =IF(Table2[[#This Row],[international_plan]]="yes",1,0) -> 0 | W15: =IF(Table2[[#This Row],[voice_mail_plan]]="yes",1,0) -> 1 | X15: =IF(B15<=$AC$3,"Low",IF(B15<=$AC$4,"Medium",IF(B15<=$AC$5,"High",IF(B15>=$AC$5,"Very High")))) -> Medium | Y15: =IF(Table2[[#This Row],[total_intl_charge]] > AVERAGE($R$2:$R$4245),"High","Low") -> High | Z15: =IF(AND(G15>AVERAGE(train!$G$2:$G$4251),K15>AVERAGE(train!$K$2:$K$4251)),"High Day & Eve",IF(AND(G15>AVERAGE(train!$G$2:$G$4251),K15<=AVERAGE(train!$K$2:$K$4251)),"High Day Only",IF(AND(G15<=AVERAGE(train!$G$2:$G$4251),K15>AVERAGE(train!$K$2:$K$4251)),"High Eve Only","Low Usage"))) -> High Day Only
A16: VA | B16: 76 | C16: area_code_510 | D16: no | E16: yes | F16: 33 | G16: 189.7 | H16: 66 | I16: 32.25 | J16: 212.8 | K16: 65 | L16: 18.09 | M16: 165.7 | N16: 108 | O16: 7.46 | P16: 10 | Q16: 5 | R16: 2.7 | S16: 1 | T16: no | U16: =IF(T16="yes",1,0) -> 0 | V16: =IF(Table2[[#This Row],[international_plan]]="yes",1,0) -> 0 | W16: =IF(Table2[[#This Row],[voice_mail_plan]]="yes",1,0) -> 1 | X16: =IF(B16<=$AC$3,"Low",IF(B16<=$AC$4,"Medium",IF(B16<=$AC$5,"High",IF(B16>=$AC$5,"Very High")))) -> Medium | Y16: =IF(Table2[[#This Row],[total_intl_charge]] > AVERAGE($R$2:$R$4245),"High","Low") -> Low | Z16: =IF(AND(G16>AVERAGE(train!$G$2:$G$4251),K16>AVERAGE(train!$K$2:$K$4251)),"High Day & Eve",IF(AND(G16>AVERAGE(train!$G$2:$G$4251),K16<=AVERAGE(train!$K$2:$K$4251)),"High Day Only",IF(AND(G16<=AVERAGE(train!$G$2:$G$4251),K16>AVERAGE(train!$K$2:$K$4251)),"High Eve Only","Low Usage"))) -> High Day Only
A17: TX | B17: 73 | C17: area_code_415 | D17: no | E17: no | F17: 0 | G17: 224.4 | H17: 90 | I17: 38.15 | J17: 159.5 | K17: 88 | L17: 13.56 | M17: 192.8 | N17: 74 | O17: 8.68 | P17: 13 | Q17: 2 | R17: 3.51 | S17: 1 | T17: no | U17: =IF(T17="yes",1,0) -> 0 | V17: =IF(Table2[[#This Row],[international_plan]]="yes",1,0) -> 0 | W17: =IF(Table2[[#This Row],[voice_mail_plan]]="yes",1,0) -> 0 | X17: =IF(B17<=$AC$3,"Low",IF(B17<=$AC$4,"Medium",IF(B17<=$AC$5,"High",IF(B17>=$AC$5,"Very High")))) -> Low | Y17: =IF(Table2[[#This Row],[total_intl_charge]] > AVERAGE($R$2:$R$4245),"High","Low") -> High | Z17: =IF(AND(G17>AVERAGE(train!$G$2:$G$4251),K17>AVERAGE(train!$K$2:$K$4251)),"High Day & Eve",IF(AND(G17>AVERAGE(train!$G$2:$G$4251),K17<=AVERAGE(train!$K$2:$K$4251)),"High Day Only",IF(AND(G17<=AVERAGE(train!$G$2:$G$4251),K17>AVERAGE(train!$K$2:$K$4251)),"High Eve Only","Low Usage"))) -> High Day Only
A18: FL | B18: 147 | C18: area_code_415 | D18: no | E18: no | F18: 0 | G18: 155.1 | H18: 117 | I18: 26.37 | J18: 239.7 | K18: 93 | L18: 20.37 | M18: 208.8 | N18: 133 | O18: 9.4 | P18: 10.6 | Q18: 4 | R18: 2.86 | S18: 0 | T18: no | U18: =IF(T18="yes",1,0) -> 0 | V18: =IF(Table2[[#This Row],[international_plan]]="yes",1,0) -> 0 | W18: =IF(Table2[[#This Row],[voice_mail_plan]]="yes",1,0) -> 0 | X18: =IF(B18<=$AC$3,"Low",IF(B18<=$AC$4,"Medium",IF(B18<=$AC$5,"High",IF(B18>=$AC$5,"Very High")))) -> Very High | Y18: =IF(Table2[[#This Row],[total_intl_charge]] > AVERAGE($R$2:$R$4245),"High","Low") -> High | Z18: =IF(AND(G18>AVERAGE(train!$G$2:$G$4251),K18>AVERAGE(train!$K$2:$K$4251)),"High Day & Eve",IF(AND(G18>AVERAGE(train!$G$2:$G$4251),K18<=AVERAGE(train!$K$2:$K$4251)),"High Day Only",IF(AND(G18<=AVERAGE(train!$G$2:$G$4251),K18>AVERAGE(train!$K$2:$K$4251)),"High Eve Only","Low Usage"))) -> Low Usage
... A4251: VT | B4251: 86 | C4251: area_code_415 | D4251: no | E4251: yes | F4251: 34 | G4251: 129.4 | H4251: 102 | I4251: 22 | J4251: 267.1 | K4251: 104 | L4251: 22.7 | M4251: 154.8 | N4251: 100 | O4251: 6.97 | P4251: 9.3 | Q4251: 16 | R4251: 2.51 | S4251: 0 | T4251: no | U4251: =IF(T4251="yes",1,0) -> 0 | V4251: =IF(Table2[[#This Row],[international_plan]]="yes",1,0) -> 0 | W4251: =IF(Table2[[#This Row],[voice_mail_plan]]="yes",1,0) -> 1 | X4251: =IF(B4251<=$AC$3,"Low",IF(B4251<=$AC$4,"Medium",IF(B4251<=$AC$5,"High",IF(B4251>=$AC$5,"Very High")))) -> Medium | Y4251: =IF(Table2[[#This Row],[total_intl_charge]] > AVERAGE($R$2:$R$4245),"High","Low") -> Low | Z4251: =IF(AND(G4251>AVERAGE(train!$G$2:$G$4251),K4251>AVERAGE(train!$K$2:$K$4251)),"High Day & Eve",IF(AND(G4251>AVERAGE(train!$G$2:$G$4251),K4251<=AVERAGE(train!$K$2:$K$4251)),"High Day Only",IF(AND(G4251<=AVERAGE(train!$G$2:$G$4251),K4251>AVERAGE(train!$K$2:$K$4251)),"High Eve Only","Low Usage"))) -> High Eve Only

Sheet Churn_Count
A1: Churn Status | B1: Count | C1: Percentage
A2: Yes | B2: =COUNTIF(train!T2:T4251,Churn_Count!A2) -> 598 | C2: =B2/B4 -> 0.140739
A3: No | B3: =COUNTIF(train!T3:T4252,Churn_Count!A3) -> 3651 | C3: =B3/B4 -> 0.859261
A4: Total | B4: =SUM(B2:B3) -> 4249

Sheet Account_Length
A1: Group | B1: Avg Account Length
A2: Churned(yes) | B2: =AVERAGEIF(train!$T$2:$T$4251,"Yes",train!$B$2:$B$4251) -> 102.13712
A3: Churned (No) | B3: =AVERAGEIF(train!$T$2:$T$4251,"No",train!$B$2:$B$4251) -> 99.924973
A4: Difference | B4: =B3-B2 -> -2.2121511
A18: Interpretation: | B18: The churned rate of longer customers is more, that means longer customers still leave maybe due to unsatisfied over time

Sheet Intl_plan
A1: International Plan | B1: Total Customers | C1: Churned | D1: Churn Rate%
A2: Yes | B2: =COUNTIF(train!$D$2:$D$4251,Intl_plan!A2) -> 396 | C2: =COUNTIFS(train!$D$2:$D$4251,A2,train!$T$2:$T$4251,"Yes") -> 167 | D2: =C2/B2 -> 0.42171717
A3: No | B3: =COUNTIF(train!$D$2:$D$4251,Intl_plan!A3) -> 3854 | C3: =COUNTIFS(train!$D$2:$D$4251,A3,train!$T$2:$T$4251,"Yes") -> 431 | D3: =C3/B3 -> 0.11183186
A4: Total | B4: =SUM(B2:B3) -> 4250 | C4: =SUM(C2:C3) -> 598

Sheet Service_Calls
A1: Group | B1: Avg Customer Service Calls
A2: Churned | B2: =AVERAGEIF(train!$T2:$T4251,"yes",train!$S2:$S4251) -> 2.2759197
A3: Not Churned | B3: =AVERAGEIF(train!$T3:$T4252,"No",train!$S3:$S4252) -> 1.4417968
A5: Insight - | B5: =IF(B2>B3,"Churned customers call MORE - dissatisfaction signal","No significant difference") -> Churned customers call MORE - dissatisfaction signal

Sheet Call_Charges
A1: Time Period | B1: Churned | C1: Not Churned
A2: Day Charge | B2: =AVERAGEIF(train!$T2:$T4251,"No",train!$I2:$I4251) -> 29.844948 | C2: =AVERAGEIF(train!$T2:$T4251,"Yes",train!$I2:$I4251) -> 35.528679
A3: Evening Charge | B3: =AVERAGEIF(train!$T3:$T4252,"No",train!$L2:$L4252) -> 17.035423 | C3: =AVERAGEIF(train!$T3:$T4252,"Yes",train!$L2:$L4252) -> 16.880886
A4: Night Charge | B4: =AVERAGEIF(train!$T4:$T4253,"No",train!$O2:$R4251) -> 9.0384082 | C4: =AVERAGEIF(train!$T4:$T4253,"Yes",train!$O2:$R4251) -> 8.9314214

Sheet Day_Minutes
A1: Group | B1: Avg Day Minutes
A2: Churned | B2: =AVERAGEIF(train!$T2:$T4521,"yes",train!$G2:$G4521) -> 208.99013
A3: Not Churned | B3: =AVERAGEIF(train!$T3:$T4522,"No",train!$G3:$G4522) -> 175.55892

Sheet Voicemail
A1: Voice Mail Plan | B1: Total | C1: Churned | D1: Churn Rate
A2: Yes | B2: =COUNTIF(train!E2:E4251,Voicemail!A2) -> 1112 | C2: =COUNTIFS(train!$E$2:$E$4251,"Yes",train!$T$2:$T$4251,"Yes") -> 82 | D2: =C2/B2 -> 0.073741007
A3: No | B3: =COUNTIF(train!E3:E4252,Voicemail!A3) -> 3138 | C3: =COUNTIFS(train!$E$2:$E$4251,"No",train!$T$2:$T$4251,"Yes") -> 516 | D3: =C3/B3 -> 0.16443595

Sheet Intl_Usage
A1: Group | B1: Avg Int Minutes | C1: Avg Int Charges
A2: Churned | B2: =AVERAGEIF(train!$T$2:$T$4251,"Yes",train!$P$2:$P$4251) -> 10.632441 | C2: =AVERAGEIF(train!$T$2:$T$4251,"Yes",train!$R$2:$R$4251) -> 2.8712542
A3: Not Churned | B3: =AVERAGEIF(train!$T$2:$T$4251,"No",train!$P$2:$P$4251) -> 10.194441 | C3: =AVERAGEIF(train!$T$2:$T$4251,"No",train!$R$2:$R$4251) -> 2.7530175

Sheet DayCalls_Correlation
A1: Correlation Result | B1: =CORREL(train!$H2:$H4251,train!$U2:$U4251) -> 0.011640422
A3: Interpretation | B3: =IF(ABS(B1)>0.5,"Strong correlation",IF(ABS(B1)>0.3,"Moderate correlation","Weak correlation")) -> Weak correlation

Sheet Eve_Charges
A1: Group | B1: Avg Evening Charges
A2: Churned | B2: =AVERAGEIF(train!$T2:$T4251,"yes",train!$L2:$L4251) -> 17.847207
A3: Not Churned | B3: =AVERAGEIF(train!$T3:$T4252,"No",train!$L3:$L4252) -> 16.878814
A4: Difference | B4: =B2-B3 -> 0.96839333

Sheet Area_Code_Churn
A1: Area Code | B1: Total Customers | C1: Churned | D1: Churn Rate%
A2: {=_xlfn.UNIQUE(train!C2:C4251)} -> area_code_415 | B2: =COUNTIF(train!C2:C4251,Area_Code_Churn!A2) -> 2108 | C2: =COUNTIFS(train!$C2:$C4251,"area_code_415",train!$T2:$T4251,"yes") -> 287 | D2: =C2/B2 -> 0.13614801
A3: area_code_408 | B3: =COUNTIF(train!C3:C4252,Area_Code_Churn!A3) -> 1086 | C3: =COUNTIFS(train!$C3:$C4252,"area_code_408",train!$T3:$T4252,"yes") -> 152 | D3: =C3/B3 -> 0.13996317
A4: area_code_510 | B4: =COUNTIF(train!C4:C4253,Area_Code_Churn!A4) -> 1056 | C4: =COUNTIFS(train!$C4:$C4253,"area_code_510",train!$T4:$T4253,"yes") -> 159 | D4: =C4/B4 -> 0.15056818

Sheet Service_Threshold
A1: Calls Range | B1: Total Customers | C1: Churned | D1: Churn Rate%
A2: 0-1 | B2: =COUNTIFS(train!$S2:$S4251,">=0",train!$S2:$S4251,"<=1") -> 2410 | C2: =COUNTIFS(train!$S2:$S4251,">=0",train!$S2:$S4251,"<=1",train!$T2:$T4251,"yes") -> 263 | D2: =C2/B2 -> 0.10912863
A3: 2-3 | B3: =COUNTIFS(train!$S3:$S4252,">=2",train!$S3:$S4252,"<=3") -> 1505 | C3: =COUNTIFS(train!$S3:$S4252,">=2",train!$S3:$S4252,"<=3",train!$T3:$T4252,"yes") -> 165 | D3: =C3/B3 -> 0.10963455
A4: 4+ | B4: =COUNTIFS(train!$S4:$S4253,">3") -> 335 | C4: =COUNTIFS(train!$S4:$S4253,">3",train!$T4:$T4253,"yes") -> 170 | D4: =C4/B4 -> 0.50746269

Sheet Account_Quartiles
A1: Quartile values
A2: (Q1) 25% | B2: =QUARTILE(train!$B2:$B4251,1) -> 73
A3: (Q2) 50% | B3: =QUARTILE(train!$B3:$B4252,2) -> 100
A4: (Q3) 75% | B4: =QUARTILE(train!$B4:$B4253,3) -> 127
A5: (Q4) 100% | B5: =QUARTILE(train!$B5:$B4254,4) -> 243
A7: Segment | B7: Total | C7: Churned | D7: Churn Rate%
A8: New(Q1) | B8: =COUNTIF(train!$B$2:$B$4251,"<="&$B2) -> 1080 | C8: =COUNTIFS(train!$B$2:$B$4251,"<="&$B2,train!$T$2:$T$4251,"yes") -> 138 | D8: =C8/B8 -> 0.12777778
A9: Growing(Q2) | B9: =COUNTIF(train!$B$2:$B$4251,"<="&$B3) -> 2169 | C9: =COUNTIFS(train!$B$2:$B$4251,"<="&$B3,train!$T$2:$T$4251,"yes") -> 294 | D9: =C9/B9 -> 0.13554633
A10: Mature(Q3) | B10: =COUNTIF(train!$B$2:$B$4251,"<="&$B4) -> 3216 | C10: =COUNTIFS(train!$B$2:$B$4251,"<="&$B4,train!$T$2:$T$4251,"yes") -> 460 | D10: =C10/B10 -> 0.14303483
A11: Total | B11: =COUNTIF(train!$B$2:$B$4251,"<="&$B5) -> 4250 | C11: =COUNTIFS(train!$B$2:$B$4251,"<="&$B5,train!$T$2:$T$4251,"yes") -> 598 | D11: =C11/B11 -> 0.14070588

Sheet Intl_Charges
A1: Median Intl Charge | B1: =MEDIAN(train!R2:R4251) -> 2.78
A3: Group | B3: Churn Count | C3: Total | D3: Churn Rate%
A4: High Intl Charge | B4: =COUNTIFS(train!$D$2:$D$4251,"yes",train!$R$2:$R$4251,">"&$B$1,train!$T$2:$T$4251,"yes") -> 103 | C4: =COUNTIFS(train!$D2:$D4251,"yes",train!$R2:$R4251,">"&$B$1) -> 211 | D4: =B4/C4 -> 0.48815166
A5: Low Intl Charge | B5: =COUNTIFS(train!$D$2:$D$4251,"yes",train!$R$2:$R$4251,"<"&$B$1,train!$T$2:$T$4251,"yes") -> 62 | C5: =COUNTIFS(train!$D2:$D4252,"yes",train!$R2:$R4252,"<"&$B$1) -> 180 | D5: =B5/C5 -> 0.34444444

Sheet Eve_Usage
A1: Median Eve Usage | B1: =MEDIAN(train!K2:K4251) -> 100
A3: Group | B3: Total | C3: Churned | D3: Churn Rate%
A4: High Eve Usage | B4: =COUNTIF(train!$K$2:$K$4251,">"&$B$1) -> 2113 | C4: =COUNTIFS(train!$K$2:$K$4251,">"&$B$1,train!$T$2:$T$4251,"yes") -> 289 | D4: =C4/B4 -> 0.13677236
A5: Low Eve Usage | B5: =COUNTIF(train!$K$2:$K$4251,"<"&$B$1) -> 2059 | C5: =COUNTIFS(train!$K$2:$K$4251,"<"&$B$1,train!$T$2:$T$4251,"yes") -> 299 | D5: =C5/B5 -> 0.14521612

Sheet Cluster_Analysis
A1: Customer_ID | B1: Day_Min | C1: Eve_Min | D1: Night_Min | E1: Intl_Min | F1: Day_Norm | G1: Eve_Norm | H1: Night_Norm | I1: Intl_Norm | J1: Cluster | K1: Churn | L1: Dist_Cluster1 | M1: Dist_Cluster2 | N1: Dist_Cluster3 | O1: Dist_Cluster4 | P1: Cluster Centers (Centroids) | V1: Reference Values | Y1: Y1: CLUSTER CENTERS
A2: =ROW()-1 -> 1 | B2: =train!G2 -> 161.6 | C2: =train!J2 -> 195.5 | D2: =train!M2 -> 254.4 | E2: =train!P2 -> 13.7 | F2: =(B2-$W$3)/($W$2-$W$3) -> 0.45974395 | G2: =(C2-$W$5)/($W$4-$W$5) -> 0.54411355 | H2: =(C2-$W$5)/($W$4-$W$5) -> 0.54411355 | I2: =(E2-$W$9)/($W$8-$W$9) -> 0.685 | J2: =MATCH(MIN(L2:O2),L2:O2,0) -> 1 | K2: =train!T2 -> no | L2: =SQRT(($F$2-$Z$3)^2+($G$2-$AA$3)^2+($H$2-$AB$3)^2+($I$2-$AC$3)^2) -> 1.1281439 | M2: =SQRT((F2-$Z$4)^2+(G2-$AA$4)^2+(H2-$AB$4)^2+(I2-$AC$4)^2) -> 1.1281439 | N2: =SQRT((F2-$Z$5)^2+(G2-$AA$5)^2+(H2-$AB$5)^2+(I2-$AC$5)^2) -> 1.1281439 | O2: =SQRT((F2-$Z$6)^2+(G2-$AA$6)^2+(H2-$AB$6)^2+(I2-$AC$6)^2) -> 1.1281439 | P2: Cluster | Q2: Day | R2: eve | S2: night | T2: Intl | V2: Day Max | W2: =MAX(B2:B4251) -> 351.5 | Y2: Y2: Cluster Z2:Day AA2:Eve AB2:Night AC2:Intl
A3: =ROW()-1 -> 2 | B3: =train!G3 -> 243.4 | C3: =train!J3 -> 121.2 | D3: =train!M3 -> 162.6 | E3: =train!P3 -> 12.2 | F3: =(B3-$W$3)/($W$2-$W$3) -> 0.69246088 | G3: =(C3-$W$5)/($W$4-$W$5) -> 0.33732257 | H3: =(C3-$W$5)/($W$4-$W$5) -> 0.33732257 | I3: =(E3-$W$9)/($W$8-$W$9) -> 0.61 | J3: =MATCH(MIN(L3:O3),L3:O3,0) -> 2 | K3: =train!T3 -> no | L3: =SQRT(($F$2-$Z$3)^2+($G$2-$AA$3)^2+($H$2-$AB$3)^2+($I$2-$AC$3)^2) -> 1.1281439 | M3: =SQRT((F3-$Z$4)^2+(G3-$AA$4)^2+(H3-$AB$4)^2+(I3-$AC$4)^2) -> 1.0388335 | N3: =SQRT((F3-$Z$5)^2+(G3-$AA$5)^2+(H3-$AB$5)^2+(I3-$AC$5)^2) -> 1.0388335 | O3: =SQRT((F3-$Z$6)^2+(G3-$AA$6)^2+(H3-$AB$6)^2+(I3-$AC$6)^2) -> 1.0388335 | P3: 1 | Q3: 0.75 | R3: 0.25 | S3: 0.25 | T3: 0.25 | V3: Day Min | W3: =MIN(B2:B4251) -> 0 | Y3: Y3: 1 Z3:0.75 AA3:0.25 AB3:0.25 AC3:0.25
A4: =ROW()-1 -> 3 | B4: =train!G4 -> 299.4 | C4: =train!J4 -> 61.9 | D4: =train!M4 -> 196.9 | E4: =train!P4 -> 6.6 | F4: =(B4-$W$3)/($W$2-$W$3) -> 0.85177809 | G4: =(C4-$W$5)/($W$4-$W$5) -> 0.17227943 | H4: =(C4-$W$5)/($W$4-$W$5) -> 0.17227943 | I4: =(E4-$W$9)/($W$8-$W$9) -> 0.33 | J4: =MATCH(MIN(L4:O4),L4:O4,0) -> 2 | K4: =train!T4 -> no | L4: =SQRT(($F$2-$Z$3)^2+($G$2-$AA$3)^2+($H$2-$AB$3)^2+($I$2-$AC$3)^2) -> 1.1281439 | M4: =SQRT((F4-$Z$4)^2+(G4-$AA$4)^2+(H4-$AB$4)^2+(I4-$AC$4)^2) -> 0.94540273 | N4: =SQRT((F4-$Z$5)^2+(G4-$AA$5)^2+(H4-$AB$5)^2+(I4-$AC$5)^2) -> 0.94540273 | O4: =SQRT((F4-$Z$6)^2+(G4-$AA$6)^2+(H4-$AB$6)^2+(I4-$AC$6)^2) -> 0.94540273 | P4: 2 | Q4: 0.25 | R4: 0.75 | S4: 0.25 | T4: 0.25 | V4: Eve Max | W4: =MAX(C2:C4251) -> 359.3 | Y4: Y4: 2 Z4:0.25 AA4:0.75 AB4:0.25 AC4:0.25
A5: =ROW()-1 -> 4 | B5: =train!G5 -> 166.7 | C5: =train!J5 -> 148.3 | D5: =train!M5 -> 186.9 | E5: =train!P5 -> 10.1 | F5: =(B5-$W$3)/($W$2-$W$3) -> 0.4742532 | G5: =(C5-$W$5)/($W$4-$W$5) -> 0.41274701 | H5: =(C5-$W$5)/($W$4-$W$5) -> 0.41274701 | I5: =(E5-$W$9)/($W$8-$W$9) -> 0.505 | J5: =MATCH(MIN(L5:O5),L5:O5,0) -> 2 | K5: =train!T5 -> no | L5: =SQRT(($F$2-$Z$3)^2+($G$2-$AA$3)^2+($H$2-$AB$3)^2+($I$2-$AC$3)^2) -> 1.1281439 | M5: =SQRT((F5-$Z$4)^2+(G5-$AA$4)^2+(H5-$AB$4)^2+(I5-$AC$4)^2) -> 0.90590357 | N5: =SQRT((F5-$Z$5)^2+(G5-$AA$5)^2+(H5-$AB$5)^2+(I5-$AC$5)^2) -> 0.90590357 | O5: =SQRT((F5-$Z$6)^2+(G5-$AA$6)^2+(H5-$AB$6)^2+(I5-$AC$6)^2) -> 0.90590357 | P5: 3 | Q5: 0.25 | R5: 0.25 | S5: 0.75 | T5: 0.25 | V5: Eve Min | W5: =MIN(C2:C4251) -> 0 | Y5: Y5: 3 Z5:0.25 AA5:0.25 AB5:0.75 AC5:0.25
A6: =ROW()-1 -> 5 | B6: =train!G6 -> 218.2 | C6: =train!J6 -> 348.5 | D6: =train!M6 -> 212.6 | E6: =train!P6 -> 7.5 | F6: =(B6-$W$3)/($W$2-$W$3) -> 0.62076814 | G6: =(C6-$W$5)/($W$4-$W$5) -> 0.96994155 | H6: =(C6-$W$5)/($W$4-$W$5) -> 0.96994155 | I6: =(E6-$W$9)/($W$8-$W$9) -> 0.375 | J6: =MATCH(MIN(L6:O6),L6:O6,0) -> 1 | K6: =train!T6 -> no | L6: =SQRT(($F$2-$Z$3)^2+($G$2-$AA$3)^2+($H$2-$AB$3)^2+($I$2-$AC$3)^2) -> 1.1281439 | M6: =SQRT((F6-$Z$4)^2+(G6-$AA$4)^2+(H6-$AB$4)^2+(I6-$AC$4)^2) -> 1.5516286 | N6: =SQRT((F6-$Z$5)^2+(G6-$AA$5)^2+(H6-$AB$5)^2+(I6-$AC$5)^2) -> 1.5516286 | O6: =SQRT((F6-$Z$6)^2+(G6-$AA$6)^2+(H6-$AB$6)^2+(I6-$AC$6)^2) -> 1.5516286 | P6: 4 | Q6: 0.25 | R6: 0.25 | S6: 0.25 | T6: 0.75 | V6: Night max | W6: =MAX(D2:D4251) -> 395 | Y6: Y6: 4 Z6:0.25 AA6:0.25 AB6:0.25 AC6:0.75
A7: =ROW()-1 -> 6 | B7: =train!G7 -> 157 | C7: =train!J7 -> 103.1 | D7: =train!M7 -> 211.8 | E7: =train!P7 -> 7.1 | F7: =(B7-$W$3)/($W$2-$W$3) -> 0.44665718 | G7: =(C7-$W$5)/($W$4-$W$5) -> 0.28694684 | H7: =(C7-$W$5)/($W$4-$W$5) -> 0.28694684 | I7: =(E7-$W$9)/($W$8-$W$9) -> 0.355 | J7: =MATCH(MIN(L7:O7),L7:O7,0) -> 2 | K7: =train!T7 -> no | L7: =SQRT(($F$2-$Z$3)^2+($G$2-$AA$3)^2+($H$2-$AB$3)^2+($I$2-$AC$3)^2) -> 1.1281439 | M7: =SQRT((F7-$Z$4)^2+(G7-$AA$4)^2+(H7-$AB$4)^2+(I7-$AC$4)^2) -> 0.70014614 | N7: =SQRT((F7-$Z$5)^2+(G7-$AA$5)^2+(H7-$AB$5)^2+(I7-$AC$5)^2) -> 0.70014614 | O7: =SQRT((F7-$Z$6)^2+(G7-$AA$6)^2+(H7-$AB$6)^2+(I7-$AC$6)^2) -> 0.70014614 | V7: Night Min | W7: =MIN(D2:D4251) -> 0
A8: =ROW()-1 -> 7 | B8: =train!G8 -> 184.5 | C8: =train!J8 -> 351.6 | D8: =train!M8 -> 215.8 | E8: =train!P8 -> 8.7 | F8: =(B8-$W$3)/($W$2-$W$3) -> 0.52489331 | G8: =(C8-$W$5)/($W$4-$W$5) -> 0.97856944 | H8: =(C8-$W$5)/($W$4-$W$5) -> 0.97856944 | I8: =(E8-$W$9)/($W$8-$W$9) -> 0.435 | J8: =MATCH(MIN(L8:O8),L8:O8,0) -> 1 | K8: =train!T8 -> no | L8: =SQRT(($F$2-$Z$3)^2+($G$2-$AA$3)^2+($H$2-$AB$3)^2+($I$2-$AC$3)^2) -> 1.1281439 | M8: =SQRT((F8-$Z$4)^2+(G8-$AA$4)^2+(H8-$AB$4)^2+(I8-$AC$4)^2) -> 1.5427036 | N8: =SQRT((F8-$Z$5)^2+(G8-$AA$5)^2+(H8-$AB$5)^2+(I8-$AC$5)^2) -> 1.5427036 | O8: =SQRT((F8-$Z$6)^2+(G8-$AA$6)^2+(H8-$AB$6)^2+(I8-$AC$6)^2) -> 1.5427036 | V8: Intl Max | W8: =MAX(E2:E4251) -> 20
A9: =ROW()-1 -> 8 | B9: =train!G9 -> 258.6 | C9: =train!J9 -> 222 | D9: =train!M9 -> 326.4 | E9: =train!P9 -> 11.2 | F9: =(B9-$W$3)/($W$2-$W$3) -> 0.73570413 | G9: =(C9-$W$5)/($W$4-$W$5) -> 0.61786808 | H9: =(C9-$W$5)/($W$4-$W$5) -> 0.61786808 | I9: =(E9-$W$9)/($W$8-$W$9) -> 0.56 | J9: =MATCH(MIN(L9:O9),L9:O9,0) -> 1 | K9: =train!T9 -> no | L9: =SQRT(($F$2-$Z$3)^2+($G$2-$AA$3)^2+($H$2-$AB$3)^2+($I$2-$AC$3)^2) -> 1.1281439 | M9: =SQRT((F9-$Z$4)^2+(G9-$AA$4)^2+(H9-$AB$4)^2+(I9-$AC$4)^2) -> 1.2721566 | N9: =SQRT((F9-$Z$5)^2+(G9-$AA$5)^2+(H9-$AB$5)^2+(I9-$AC$5)^2) -> 1.2721566 | O9: =SQRT((F9-$Z$6)^2+(G9-$AA$6)^2+(H9-$AB$6)^2+(I9-$AC$6)^2) -> 1.2721566 | V9: Intl Min | W9: =MIN(E2:E4251) -> 0
A10: =ROW()-1 -> 9 | B10: =train!G10 -> 129.1 | C10: =train!J10 -> 228.5 | D10: =train!M10 -> 208.8 | E10: =train!P10 -> 12.7 | F10: =(B10-$W$3)/($W$2-$W$3) -> 0.36728307 | G10: =(C10-$W$5)/($W$4-$W$5) -> 0.63595881 | H10: =(C10-$W$5)/($W$4-$W$5) -> 0.63595881 | I10: =(E10-$W$9)/($W$8-$W$9) -> 0.635 | J10: =MATCH(MIN(L10:O10),L10:O10,0) -> 1 | K10: =train!T10 -> yes | L10: =SQRT(($F$2-$Z$3)^2+($G$2-$AA$3)^2+($H$2-$AB$3)^2+($I$2-$AC$3)^2) -> 1.1281439 | M10: =SQRT((F10-$Z$4)^2+(G10-$AA$4)^2+(H10-$AB$4)^2+(I10-$AC$4)^2) -> 1.1606072 | N10: =SQRT((F10-$Z$5)^2+(G10-$AA$5)^2+(H10-$AB$5)^2+(I10-$AC$5)^2) -> 1.1606072 | O10: =SQRT((F10-$Z$6)^2+(G10-$AA$6)^2+(H10-$AB$6)^2+(I10-$AC$6)^2) -> 1.1606072
A11: =ROW()-1 -> 10 | B11: =train!G11 -> 187.7 | C11: =train!J11 -> 163.4 | D11: =train!M11 -> 196 | E11: =train!P11 -> 9.1 | F11: =(B11-$W$3)/($W$2-$W$3) -> 0.53399716 | G11: =(C11-$W$5)/($W$4-$W$5) -> 0.45477317 | H11: =(C11-$W$5)/($W$4-$W$5) -> 0.45477317 | I11: =(E11-$W$9)/($W$8-$W$9) -> 0.455 | J11: =MATCH(MIN(L11:O11),L11:O11,0) -> 2 | K11: =train!T11 -> no | L11: =SQRT(($F$2-$Z$3)^2+($G$2-$AA$3)^2+($H$2-$AB$3)^2+($I$2-$AC$3)^2) -> 1.1281439 | M11: =SQRT((F11-$Z$4)^2+(G11-$AA$4)^2+(H11-$AB$4)^2+(I11-$AC$4)^2) -> 0.95174326 | N11: =SQRT((F11-$Z$5)^2+(G11-$AA$5)^2+(H11-$AB$5)^2+(I11-$AC$5)^2) -> 0.95174326 | O11: =SQRT((F11-$Z$6)^2+(G11-$AA$6)^2+(H11-$AB$6)^2+(I11-$AC$6)^2) -> 0.95174326
A12: =ROW()-1 -> 11 | B12: =train!G12 -> 128.8 | C12: =train!J12 -> 104.9 | D12: =train!M12 -> 141.1 | E12: =train!P12 -> 11.2 | F12: =(B12-$W$3)/($W$2-$W$3) -> 0.36642959 | G12: =(C12-$W$5)/($W$4-$W$5) -> 0.29195658 | H12: =(C12-$W$5)/($W$4-$W$5) -> 0.29195658 | I12: =(E12-$W$9)/($W$8-$W$9) -> 0.56 | J12: =MATCH(MIN(L12:O12),L12:O12,0) -> 2 | K12: =train!T12 -> no | L12: =SQRT(($F$2-$Z$3)^2+($G$2-$AA$3)^2+($H$2-$AB$3)^2+($I$2-$AC$3)^2) -> 1.1281439 | M12: =SQRT((F12-$Z$4)^2+(G12-$AA$4)^2+(H12-$AB$4)^2+(I12-$AC$4)^2) -> 0.78635102 | N12: =SQRT((F12-$Z$5)^2+(G12-$AA$5)^2+(H12-$AB$5)^2+(I12-$AC$5)^2) -> 0.78635102 | O12: =SQRT((F12-$Z$6)^2+(G12-$AA$6)^2+(H12-$AB$6)^2+(I12-$AC$6)^2) -> 0.78635102
A13: =ROW()-1 -> 12 | B13: =train!G13 -> 156.6 | C13: =train!J13 -> 247.6 | D13: =train!M13 -> 192.3 | E13: =train!P13 -> 12.3 | F13: =(B13-$W$3)/($W$2-$W$3) -> 0.4455192 | G13: =(C13-$W$5)/($W$4-$W$5) -> 0.68911773 | H13: =(C13-$W$5)/($W$4-$W$5) -> 0.68911773 | I13: =(E13-$W$9)/($W$8-$W$9) -> 0.615 | J13: =MATCH(MIN(L13:O13),L13:O13,0) -> 1 | K13: =train!T13 -> no | L13: =SQRT(($F$2-$Z$3)^2+($G$2-$AA$3)^2+($H$2-$AB$3)^2+($I$2-$AC$3)^2) -> 1.1281439 | M13: =SQRT((F13-$Z$4)^2+(G13-$AA$4)^2+(H13-$AB$4)^2+(I13-$AC$4)^2) -> 1.2355075 | N13: =SQRT((F13-$Z$5)^2+(G13-$AA$5)^2+(H13-$AB$5)^2+(I13-$AC$5)^2) -> 1.2355075 | O13: =SQRT((F13-$Z$6)^2+(G13-$AA$6)^2+(H13-$AB$6)^2+(I13-$AC$6)^2) -> 1.2355075
A14: =ROW()-1 -> 13 | B14: =train!G14 -> 332.9 | C14: =train!J14 -> 317.8 | D14: =train!M14 -> 160.6 | E14: =train!P14 -> 5.4 | F14: =(B14-$W$3)/($W$2-$W$3) -> 0.94708393 | G14: =(C14-$W$5)/($W$4-$W$5) -> 0.88449763 | H14: =(C14-$W$5)/($W$4-$W$5) -> 0.88449763 | I14: =(E14-$W$9)/($W$8-$W$9) -> 0.27 | J14: =MATCH(MIN(L14:O14),L14:O14,0) -> 1 | K14: =train!T14 -> yes | L14: =SQRT(($F$2-$Z$3)^2+($G$2-$AA$3)^2+($H$2-$AB$3)^2+($I$2-$AC$3)^2) -> 1.1281439 | M14: =SQRT((F14-$Z$4)^2+(G14-$AA$4)^2+(H14-$AB$4)^2+(I14-$AC$4)^2) -> 1.5920239 | N14: =SQRT((F14-$Z$5)^2+(G14-$AA$5)^2+(H14-$AB$5)^2+(I14-$AC$5)^2) -> 1.5920239 | O14: =SQRT((F14-$Z$6)^2+(G14-$AA$6)^2+(H14-$AB$6)^2+(I14-$AC$6)^2) -> 1.5920239
A15: =ROW()-1 -> 14 | B15: =train!G15 -> 196.4 | C15: =train!J15 -> 280.9 | D15: =train!M15 -> 89.3 | E15: =train!P15 -> 13.8 | F15: =(B15-$W$3)/($W$2-$W$3) -> 0.55874822 | G15: =(C15-$W$5)/($W$4-$W$5) -> 0.78179794 | H15: =(C15-$W$5)/($W$4-$W$5) -> 0.78179794 | I15: =(E15-$W$9)/($W$8-$W$9) -> 0.69 | J15: =MATCH(MIN(L15:O15),L15:O15,0) -> 1 | K15: =train!T15 -> no | L15: =SQRT(($F$2-$Z$3)^2+($G$2-$AA$3)^2+($H$2-$AB$3)^2+($I$2-$AC$3)^2) -> 1.1281439 | M15: =SQRT((F15-$Z$4)^2+(G15-$AA$4)^2+(H15-$AB$4)^2+(I15-$AC$4)^2) -> 1.417997 | N15: =SQRT((F15-$Z$5)^2+(G15-$AA$5)^2+(H15-$AB$5)^2+(I15-$AC$5)^2) -> 1.417997 | O15: =SQRT((F15-$Z$6)^2+(G15-$AA$6)^2+(H15-$AB$6)^2+(I15-$AC$6)^2) -> 1.417997
A16: =ROW()-1 -> 15 | B16: =train!G16 -> 189.7 | C16: =train!J16 -> 212.8 | D16: =train!M16 -> 165.7 | E16: =train!P16 -> 10 | F16: =(B16-$W$3)/($W$2-$W$3) -> 0.53968706 | G16: =(C16-$W$5)/($W$4-$W$5) -> 0.59226273 | H16: =(C16-$W$5)/($W$4-$W$5) -> 0.59226273 | I16: =(E16-$W$9)/($W$8-$W$9) -> 0.5 | J16: =MATCH(MIN(L16:O16),L16:O16,0) -> 2 | K16: =train!T16 -> no | L16: =SQRT(($F$2-$Z$3)^2+($G$2-$AA$3)^2+($H$2-$AB$3)^2+($I$2-$AC$3)^2) -> 1.1281439 | M16: =SQRT((F16-$Z$4)^2+(G16-$AA$4)^2+(H16-$AB$4)^2+(I16-$AC$4)^2) -> 1.114815 | N16: =SQRT((F16-$Z$5)^2+(G16-$AA$5)^2+(H16-$AB$5)^2+(I16-$AC$5)^2) -> 1.114815 | O16: =SQRT((F16-$Z$6)^2+(G16-$AA$6)^2+(H16-$AB$6)^2+(I16-$AC$6)^2) -> 1.114815
A17: =ROW()-1 -> 16 | B17: =train!G17 -> 224.4 | C17: =train!J17 -> 159.5 | D17: =train!M17 -> 192.8 | E17: =train!P17 -> 13 | F17: =(B17-$W$3)/($W$2-$W$3) -> 0.63840683 | G17: =(C17-$W$5)/($W$4-$W$5) -> 0.44391873 | H17: =(C17-$W$5)/($W$4-$W$5) -> 0.44391873 | I17: =(E17-$W$9)/($W$8-$W$9) -> 0.65 | J17: =MATCH(MIN(L17:O17),L17:O17,0) -> 2 | K17: =train!T17 -> no | L17: =SQRT(($F$2-$Z$3)^2+($G$2-$AA$3)^2+($H$2-$AB$3)^2+($I$2-$AC$3)^2) -> 1.1281439 | M17: =SQRT((F17-$Z$4)^2+(G17-$AA$4)^2+(H17-$AB$4)^2+(I17-$AC$4)^2) -> 1.1064316 | N17: =SQRT((F17-$Z$5)^2+(G17-$AA$5)^2+(H17-$AB$5)^2+(I17-$AC$5)^2) -> 1.1064316 | O17: =SQRT((F17-$Z$6)^2+(G17-$AA$6)^2+(H17-$AB$6)^2+(I17-$AC$6)^2) -> 1.1064316
A18: =ROW()-1 -> 17 | B18: =train!G18 -> 155.1 | C18: =train!J18 -> 239.7 | D18: =train!M18 -> 208.8 | E18: =train!P18 -> 10.6 | F18: =(B18-$W$3)/($W$2-$W$3) -> 0.44125178 | G18: =(C18-$W$5)/($W$4-$W$5) -> 0.66713053 | H18: =(C18-$W$5)/($W$4-$W$5) -> 0.66713053 | I18: =(E18-$W$9)/($W$8-$W$9) -> 0.53 | J18: =MATCH(MIN(L18:O18),L18:O18,0) -> 1 | K18: =train!T18 -> no | L18: =SQRT(($F$2-$Z$3)^2+($G$2-$AA$3)^2+($H$2-$AB$3)^2+($I$2-$AC$3)^2) -> 1.1281439 | M18: =SQRT((F18-$Z$4)^2+(G18-$AA$4)^2+(H18-$AB$4)^2+(I18-$AC$4)^2) -> 1.1686443 | N18: =SQRT((F18-$Z$5)^2+(G18-$AA$5)^2+(H18-$AB$5)^2+(I18-$AC$5)^2) -> 1.1686443 | O18: =SQRT((F18-$Z$6)^2+(G18-$AA$6)^2+(H18-$AB$6)^2+(I18-$AC$6)^2) -> 1.1686443
A19: =ROW()-1 -> 18 | B19: =train!G19 -> 62.4 | C19: =train!J19 -> 169.9 | D19: =train!M19 -> 209.6 | E19: =train!P19 -> 5.7 | F19: =(B19-$W$3)/($W$2-$W$3) -> 0.17752489 | G19: =(C19-$W$5)/($W$4-$W$5) -> 0.4728639 | H19: =(C19-$W$5)/($W$4-$W$5) -> 0.4728639 | I19: =(E19-$W$9)/($W$8-$W$9) -> 0.285 | J19: =MATCH(MIN(L19:O19),L19:O19,0) -> 2 | K19: =train!T19 -> yes | L19: =SQRT(($F$2-$Z$3)^2+($G$2-$AA$3)^2+($H$2-$AB$3)^2+($I$2-$AC$3)^2) -> 1.1281439 | M19: =SQRT((F19-$Z$4)^2+(G19-$AA$4)^2+(H19-$AB$4)^2+(I19-$AC$4)^2) -> 0.74829181 | N19: =SQRT((F19-$Z$5)^2+(G19-$AA$5)^2+(H19-$AB$5)^2+(I19-$AC$5)^2) -> 0.74829181 | O19: =SQRT((F19-$Z$6)^2+(G19-$AA$6)^2+(H19-$AB$6)^2+(I19-$AC$6)^2) -> 0.74829181
A20: =ROW()-1 -> 19 | B20: =train!G20 -> 183 | C20: =train!J20 -> 72.9 | D20: =train!M20 -> 181.8 | E20: =train!P20 -> 9.5 | F20: =(B20-$W$3)/($W$2-$W$3) -> 0.52062589 | G20: =(C20-$W$5)/($W$4-$W$5) -> 0.20289452 | H20: =(C20-$W$5)/($W$4-$W$5) -> 0.20289452 | I20: =(E20-$W$9)/($W$8-$W$9) -> 0.475 | J20: =MATCH(MIN(L20:O20),L20:O20,0) -> 2 | K20: =train!T20 -> no | L20: =SQRT(($F$2-$Z$3)^2+($G$2-$AA$3)^2+($H$2-$AB$3)^2+($I$2-$AC$3)^2) -> 1.1281439 | M20: =SQRT((F20-$Z$4)^2+(G20-$AA$4)^2+(H20-$AB$4)^2+(I20-$AC$4)^2) -> 0.7609262 | N20: =SQRT((F20-$Z$5)^2+(G20-$AA$5)^2+(H20-$AB$5)^2+(I20-$AC$5)^2) -> 0.7609262 | O20: =SQRT((F20-$Z$6)^2+(G20-$AA$6)^2+(H20-$AB$6)^2+(I20-$AC$6)^2) -> 0.7609262
A21: =ROW()-1 -> 20 | B21: =train!G21 -> 110.4 | C21: =train!J21 -> 137.3 | D21: =train!M21 -> 189.6 | E21: =train!P21 -> 7.7 | F21: =(B21-$W$3)/($W$2-$W$3) -> 0.3140825 | G21: =(C21-$W$5)/($W$4-$W$5) -> 0.38213192 | H21: =(C21-$W$5)/($W$4-$W$5) -> 0.38213192 | I21: =(E21-$W$9)/($W$8-$W$9) -> 0.385 | J21: =MATCH(MIN(L21:O21),L21:O21,0) -> 2 | K21: =train!T21 -> no | L21: =SQRT(($F$2-$Z$3)^2+($G$2-$AA$3)^2+($H$2-$AB$3)^2+($I$2-$AC$3)^2) -> 1.1281439 | M21: =SQRT((F21-$Z$4)^2+(G21-$AA$4)^2+(H21-$AB$4)^2+(I21-$AC$4)^2) -> 0.73411336 | N21: =SQRT((F21-$Z$5)^2+(G21-$AA$5)^2+(H21-$AB$5)^2+(I21-$AC$5)^2) -> 0.73411336 | O21: =SQRT((F21-$Z$6)^2+(G21-$AA$6)^2+(H21-$AB$6)^2+(I21-$AC$6)^2) -> 0.73411336
... A4251: =ROW()-1 -> 4250 | B4251: =train!G4251 -> 129.4 | C4251: =train!J4251 -> 267.1 | D4251: =train!M4251 -> 154.8 | E4251: =train!P4251 -> 9.3 | F4251: =(B4251-$W$3)/($W$2-$W$3) -> 0.36813656 | G4251: =(C4251-$W$5)/($W$4-$W$5) -> 0.74338992 | H4251: =(C4251-$W$5)/($W$4-$W$5) -> 0.74338992 | I4251: =(E4251-$W$9)/($W$8-$W$9) -> 0.465 | J4251: =MATCH(MIN(L4251:O4251),L4251:O4251,0) -> 1 | K4251: =train!T4251 -> no | L4251: =SQRT(($F$2-$Z$3)^2+($G$2-$AA$3)^2+($H$2-$AB$3)^2+($I$2-$AC$3)^2) -> 1.1281439 | M4251: =SQRT((F4251-$Z$4)^2+(G4251-$AA$4)^2+(H4251-$AB$4)^2+(I4251-$AC$4)^2) -> 1.2070653 | N4251: =SQRT((F4251-$Z$5)^2+(G4251-$AA$5)^2+(H4251-$AB$5)^2+(I4251-$AC$5)^2) -> 1.2070653 | O4251: =SQRT((F4251-$Z$6)^2+(G4251-$AA$6)^2+(H4251-$AB$6)^2+(I4251-$AC$6)^2) -> 1.2070653

Sheet Cluster_Results
A1: Cluster Analysis results
A3: Cluster | B3: Total | C3: Churned | D3: Churn% | E3: Description | F3: Strategy | G3: Avg Day Min | H3: Avg Eve Min | I3: Avg Night Min | J3: Avg Intl Min
A4: Cluster 1 | B4: =COUNTIF(Cluster_Analysis!$J:$J,1) -> 1755 | C4: =COUNTIFS(Cluster_Analysis!$J:$J,1,Cluster_Analysis!$K:$K,"yes") -> 361 | D4: =IFERROR(C4/B4,0) -> 0.20569801 | E4: =IF(G4=MAX($G$4:$G$7),"Heavy Day Users",IF(H4=MAX($H$4:$H$7),"Heavy Evening Users",IF(I4=MAX($I$4:$I$7),"Heavy Night Users","Heavy Intl Users"))) -> Heavy Day Users | F4: Target with premium day call packages | G4: =AVERAGEIF(Cluster_Analysis!$J:$J,1,Cluster_Analysis!$B:$B) -> 199.54399 | H4: =AVERAGEIF(Cluster_Analysis!$J:$J,1,Cluster_Analysis!$C:$C) -> 239.65248 | I4: =AVERAGEIF(Cluster_Analysis!$J:$J,1,Cluster_Analysis!$D:$D) -> 200.15362 | J4: =AVERAGEIF(Cluster_Analysis!$J:$J,1,Cluster_Analysis!$E:$E) -> 11.155613
A5: Cluster 2 | B5: =COUNTIF(Cluster_Analysis!$J:$J,2) -> 2495 | C5: =COUNTIFS(Cluster_Analysis!$J:$J,2,Cluster_Analysis!$K:$K,"yes") -> 237 | D5: =IFERROR(C5/B5,0) -> 0.09498998 | E5: =IF(G5=MAX($G$4:$G$7),"Heavy Day Users",IF(H5=MAX($H$4:$H$7),"Heavy Evening Users",IF(I5=MAX($I$4:$I$7),"Heavy Night Users","Heavy Intl Users"))) -> Heavy Night Users | F5: Offer evening bundle discounts | G5: =AVERAGEIF(Cluster_Analysis!$J:$J,2,Cluster_Analysis!$B:$B) -> 166.69483 | H5: =AVERAGEIF(Cluster_Analysis!$J:$J,2,Cluster_Analysis!$C:$C) -> 172.40441 | I5: =AVERAGEIF(Cluster_Analysis!$J:$J,2,Cluster_Analysis!$D:$D) -> 200.79114 | J5: =AVERAGEIF(Cluster_Analysis!$J:$J,2,Cluster_Analysis!$E:$E) -> 9.6233267
A6: Cluster 3 | B6: =COUNTIF(Cluster_Analysis!$J:$J,3) -> 0 | C6: =COUNTIFS(Cluster_Analysis!$J:$J,3,Cluster_Analysis!$K:$K,"yes") -> 0 | D6: =IFERROR(C6/B6,0) -> 0 | E6: =IF(G6=MAX($G$4:$G$7),"Heavy Day Users",IF(H6=MAX($H$4:$H$7),"Heavy Evening Users",IF(I6=MAX($I$4:$I$7),"Heavy Night Users","Heavy Intl Users"))) -> Heavy Intl Users | F6: Night owl special rates | G6: =IFERROR(AVERAGEIF(Cluster_Analysis!$J:$J,3,Cluster_Analysis!$B:$B),0) -> 0 | H6: =IFERROR(AVERAGEIF(Cluster_Analysis!$J:$J,3,Cluster_Analysis!$C:$C),0) -> 0 | I6: =IFERROR(AVERAGEIF(Cluster_Analysis!$J:$J,3,Cluster_Analysis!$D:$D),0) -> 0 | J6: =IFERROR(AVERAGEIF(Cluster_Analysis!$J:$J,3,Cluster_Analysis!$E:$E),0) -> 0
A7: Cluster 4 | B7: =COUNTIF(Cluster_Analysis!$J:$J,4) -> 0 | C7: =COUNTIFS(Cluster_Analysis!$J:$J,4,Cluster_Analysis!$K:$K,"yes") -> 0 | D7: =IFERROR(C7/B7,0) -> 0 | E7: =IF(G7=MAX($G$4:$G$7),"Heavy Day Users",IF(H7=MAX($H$4:$H$7),"Heavy Evening Users",IF(I7=MAX($I$4:$I$7),"Heavy Night Users","Heavy Intl Users"))) -> Heavy Intl Users | F7: International plan upgrade offers | G7: =IFERROR(AVERAGEIF(Cluster_Analysis!$J:$J,4,Cluster_Analysis!$B:$B),0) -> 0 | H7: =IFERROR(AVERAGEIF(Cluster_Analysis!$J:$J,4,Cluster_Analysis!$C:$C),0) -> 0 | I7: =IFERROR(AVERAGEIF(Cluster_Analysis!$J:$J,4,Cluster_Analysis!$D:$D),0) -> 0 | J7: =IFERROR(AVERAGEIF(Cluster_Analysis!$J:$J,4,Cluster_Analysis!$E:$E),0) -> 0
A8: Total | B8: =SUM(B4:B7) -> 4250 | C8: =SUM(C4:C7) -> 598
A12: CLUSTER INTERPRETATION SUMMARY
A14: Finding 1 | B14: =IF(MAX(D4:D7)=D4,"Cluster 1 has highest churn risk", IF(MAX(D4:D7)=D5,"Cluster 2 has highest churn risk", IF(MAX(D4:D7)=D6,"Cluster 3 has highest churn risk", "Cluster 4 has highest churn risk"))) -> Cluster 1 has highest churn risk
A15: Highest Risk Cluster Churn Rate | B15: =MAX(D4:D7) -> 0.20569801
A16: Lowest Risk Cluster Churn Rate | B16: =MIN(D4:D7)&"%" -> 0%
A17: Total Customers Analyzed | B17: =B8 -> 4250

Sheet Voicemail_Churn
A1: Group | B1: Voice Mail | C1: Volume of Voice Mail
A2: Churned | B2: =COUNTIFS(train!E2:E4251,"yes",train!T2:T4251,"yes") -> 82 | C2: =SUMIFS(train!F2:F4251,train!E2:E4251,"yes",train!T2:T4251,"yes") -> 2571
A3: Not Churned | B3: =COUNTIFS(train!E2:E4251,"yes",train!T2:T4251,"No") -> 1030 | C3: =SUMIFS(train!F2:F4251,train!E2:E4251,"yes",train!T2:T4251,"No") -> 29864
A4: Total | B4: =SUM(B2:B3) -> 1112 | C4: =SUM(C2:C3) -> 32435

Sheet DAY MINUTES & CHARGES vs CHURN 
A1: DAY MINUTES & CHARGES vs CHURN | H1: DAY Minutes | I1: Day charges | J1: churn(1=yes, 0=no)
H2: =train!G2 -> 161.6 | I2: =train!I2 -> 27.47 | J2: =IF(train!T2="yes",1,0) -> 0
A3: BASIC STATISTICS | H3: =train!G3 -> 243.4 | I3: =train!I3 -> 41.38 | J3: =IF(train!T3="yes",1,0) -> 0
A4: Metric | B4: Churned | C4: Not Churned | H4: =train!G4 -> 299.4 | I4: =train!I4 -> 50.9 | J4: =IF(train!T4="yes",1,0) -> 0
A5: Avg Day Min | B5: =AVERAGEIF(train!$T:$T,"yes",train!$G:$G) -> 208.99013 | C5: =AVERAGEIF(train!$T:$T,"No",train!$G:$G) -> 175.55509 | H5: =train!G5 -> 166.7 | I5: =train!I5 -> 28.34 | J5: =IF(train!T5="yes",1,0) -> 0
A6: Avg Day charges | B6: =AVERAGEIF(train!$T:$T,"yes",train!$I:$I) -> 35.528679 | C6: =AVERAGEIF(train!$T:$T,"No",train!$I:$I) -> 29.844948 | H6: =train!G6 -> 218.2 | I6: =train!I6 -> 37.09 | J6: =IF(train!T6="yes",1,0) -> 0
A7: Min Day minutes | B7: =_xlfn.MINIFS(train!$G:$G,train!$T:$T,"yes") -> 0 | C7: =_xlfn.MINIFS(train!$G:$G,train!$T:$T,"no") -> 0 | H7: =train!G7 -> 157 | I7: =train!I7 -> 26.69 | J7: =IF(train!T7="yes",1,0) -> 0
A8: Max Day minutes | B8: =_xlfn.MAXIFS(train!$G:$G,train!$T:$T,"yes") -> 351.5 | C8: =_xlfn.MAXIFS(train!$G:$G,train!$T:$T,"no") -> 313.8 | H8: =train!G8 -> 184.5 | I8: =train!I8 -> 31.37 | J8: =IF(train!T8="yes",1,0) -> 0
A9: Min Day Charges | B9: =_xlfn.MINIFS(train!$I:$I,train!$T:$T,"yes") -> 0 | C9: =_xlfn.MINIFS(train!$I:$I,train!$T:$T,"no") -> 0 | H9: =train!G9 -> 258.6 | I9: =train!I9 -> 43.96 | J9: =IF(train!T9="yes",1,0) -> 0
A10: Max Day Charges | B10: =_xlfn.MAXIFS(train!$I:$I,train!$T:$T,"yes") -> 59.76 | C10: =_xlfn.MAXIFS(train!$I:$I,train!$T:$T,"no") -> 53.35 | H10: =train!G10 -> 129.1 | I10: =train!I10 -> 21.95 | J10: =IF(train!T10="yes",1,0) -> 1
H11: =train!G11 -> 187.7 | I11: =train!I11 -> 31.91 | J11: =IF(train!T11="yes",1,0) -> 0
H12: =train!G12 -> 128.8 | I12: =train!I12 -> 21.9 | J12: =IF(train!T12="yes",1,0) -> 0
A13: CHURN RATE BY DAY MINUTES SEGMENTS | H13: =train!G13 -> 156.6 | I13: =train!I13 -> 26.62 | J13: =IF(train!T13="yes",1,0) -> 0
A14: Minutes Range | B14: Total | C14: Churned | D14: Not Churned | E14: Churn% | H14: =train!G14 -> 332.9 | I14: =train!I14 -> 56.59 | J14: =IF(train!T14="yes",1,0) -> 1
A15: 0-100 | B15: =COUNTIFS(train!$G:$G,">=0",train!$G:$G,"<=100") -> 296 | C15: =COUNTIFS(train!$G:$G,">=0",train!$G:$G,"<=100",train!$T:$T,"yes") -> 33 | D15: =B15-C15 -> 263 | E15: =IF(B15=0,0,C15/B15*100) -> 11.148649 | H15: =train!G15 -> 196.4 | I15: =train!I15 -> 33.39 | J15: =IF(train!T15="yes",1,0) -> 0
A16: 101-150 | B16: =COUNTIFS(train!$G:$G,">=101",train!$G:$G,"<=150") -> 943 | C16: =COUNTIFS(train!$G:$G,">=101",train!$G:$G,"<=150",train!$T:$T,"yes") -> 115 | D16: =B16-C16 -> 828 | E16: =IF(B16=0,0,C16/B16*100) -> 12.195122 | H16: =train!G16 -> 189.7 | I16: =train!I16 -> 32.25 | J16: =IF(train!T16="yes",1,0) -> 0
A17: 151-175 | B17: =COUNTIFS(train!$G:$G,">=151",train!$G:$G,"<=175") -> 684 | C17: =COUNTIFS(train!$G:$G,">=151",train!$G:$G,"<=175",train!$T:$T,"yes") -> 65 | D17: =B17-C17 -> 619 | E17: =IF(B17=0,0,C17/B17*100) -> 9.502924 | H17: =train!G17 -> 224.4 | I17: =train!I17 -> 38.15 | J17: =IF(train!T17="yes",1,0) -> 0
A18: 176-200 | B18: =COUNTIFS(train!$G:$G,">=176",train!$G:$G,"<=200") -> 755 | C18: =COUNTIFS(train!$G:$G,">=176",train!$G:$G,"<=200",train!$T:$T,"yes") -> 52 | D18: =B18-C18 -> 703 | E18: =IF(B18=0,0,C18/B18*100) -> 6.8874172 | H18: =train!G18 -> 155.1 | I18: =train!I18 -> 26.37 | J18: =IF(train!T18="yes",1,0) -> 0
A19: 201-225 | B19: =COUNTIFS(train!$G:$G,">=201",train!$G:$G,"<=225") -> 635 | C19: =COUNTIFS(train!$G:$G,">=201",train!$G:$G,"<=225",train!$T:$T,"yes") -> 43 | D19: =B19-C19 -> 592 | E19: =IF(B19=0,0,C19/B19*100) -> 6.7716535 | H19: =train!G19 -> 62.4 | I19: =train!I19 -> 10.61 | J19: =IF(train!T19="yes",1,0) -> 1
A20: 226-250 | B20: =COUNTIFS(train!$G:$G,">=226",train!$G:$G,"<=250") -> 407 | C20: =COUNTIFS(train!$G:$G,">=226",train!$G:$G,"<=250",train!$T:$T,"yes") -> 71 | D20: =B20-C20 -> 336 | E20: =IF(B20=0,0,C20/B20*100) -> 17.444717 | H20: =train!G20 -> 183 | I20: =train!I20 -> 31.11 | J20: =IF(train!T20="yes",1,0) -> 0
A21: 251-275 | B21: =COUNTIFS(train!$G:$G,">=251",train!$G:$G,"<=275") -> 249 | C21: =COUNTIFS(train!$G:$G,">=251",train!$G:$G,"<=275",train!$T:$T,"yes") -> 96 | D21: =B21-C21 -> 153 | E21: =IF(B21=0,0,C21/B21*100) -> 38.554217 | H21: =train!G21 -> 110.4 | I21: =train!I21 -> 18.77 | J21: =IF(train!T21="yes",1,0) -> 0
A22: 276-300 | B22: =COUNTIFS(train!$G:$G,">=276",train!$G:$G,"<=300") -> 103 | C22: =COUNTIFS(train!$G:$G,">=276",train!$G:$G,"<=300",train!$T:$T,"yes") -> 59 | D22: =B22-C22 -> 44 | E22: =IF(B22=0,0,C22/B22*100) -> 57.281553 | H22: =train!G22 -> 81.1 | I22: =train!I22 -> 13.79 | J22: =IF(train!T22="yes",1,0) -> 0
A23: 301+ | B23: =COUNTIFS(train!$G:$G,">=301") -> 55 | C23: =COUNTIFS(train!$G:$G,">=301",train!$T:$T,"yes") -> 45 | D23: =B23-C23 -> 10 | E23: =IF(B23=0,0,C23/B23*100) -> 81.818182 | H23: =train!G23 -> 213 | I23: =train!I23 -> 36.21 | J23: =IF(train!T23="yes",1,0) -> 0
H24: =train!G24 -> 134.3 | I24: =train!I24 -> 22.83 | J24: =IF(train!T24="yes",1,0) -> 0
H25: =train!G25 -> 190 | I25: =train!I25 -> 32.3 | J25: =IF(train!T25="yes",1,0) -> 0
A26: Inflection point finder | H26: =train!G26 -> 119.3 | I26: =train!I26 -> 20.28 | J26: =IF(train!T26="yes",1,0) -> 0
A27: Overall Avg churn rate | B27: =COUNTIF(train!$T:$T,"yes")/COUNTA(train!$A2:$A4251)*100 -> 14.070588 | H27: =train!G27 -> 226.1 | I27: =train!I27 -> 38.44 | J27: =IF(train!T27="yes",1,0) -> 0
A28: Highest churn rate segment | B28: =MAX(E15:E23) -> 81.818182 | H28: =train!G28 -> 249.6 | I28: =train!I28 -> 42.43 | J28: =IF(train!T28="yes",1,0) -> 1
A29: Inflection Point (where churn jumps): | B29: =INDEX(A15:A23,MATCH(MAX(E15:E23),E15:E23,0)) -> 301+ | H29: =train!G29 -> 176.8 | I29: =train!I29 -> 30.06 | J29: =IF(train!T29="yes",1,0) -> 0
A30: Churn Rate BEFORE tipping point: | B30: =AVERAGE(E15:E19) -> 9.3011531 | H30: =train!G30 -> 146.3 | I30: =train!I30 -> 24.87 | J30: =IF(train!T30="yes",1,0) -> 0
A31: Churn Rate AFTER tipping point: | B31: =AVERAGE(E20:E23) -> 48.774667 | H31: =train!G31 -> 130.8 | I31: =train!I31 -> 22.24 | J31: =IF(train!T31="yes",1,0) -> 0
A32: Churn increase after tipping point: | B32: =B31-B30 -> 39.473514 | H32: =train!G32 -> 203.9 | I32: =train!I32 -> 34.66 | J32: =IF(train!T32="yes",1,0) -> 0
A33: Conclusion: | B33: =IF(B32>5,"YES - Clear inflection point exists. Higher usage = Higher churn","Weak inflection - usage alone may not drive churn") -> YES - Clear inflection point exists. Higher usage = Higher churn | H33: =train!G33 -> 126.3 | I33: =train!I33 -> 21.47 | J33: =IF(train!T33="yes",1,0) -> 0
H34: =train!G34 -> 173.1 | I34: =train!I34 -> 29.43 | J34: =IF(train!T34="yes",1,0) -> 1
H35: =train!G35 -> 124.8 | I35: =train!I35 -> 21.22 | J35: =IF(train!T35="yes",1,0) -> 0
H36: =train!G36 -> 85.8 | I36: =train!I36 -> 14.59 | J36: =IF(train!T36="yes",1,0) -> 0
H37: =train!G37 -> 154 | I37: =train!I37 -> 26.18 | J37: =IF(train!T37="yes",1,0) -> 0
H38: =train!G38 -> 120.9 | I38: =train!I38 -> 20.55 | J38: =IF(train!T38="yes",1,0) -> 0
H39: =train!G39 -> 211.3 | I39: =train!I39 -> 35.92 | J39: =IF(train!T39="yes",1,0) -> 0
H40: =train!G40 -> 187 | I40: =train!I40 -> 31.79 | J40: =IF(train!T40="yes",1,0) -> 0
...

Sheet Intl_plan_churn
A2: Group | B2: Total | C2: Intl Calls | D2: Churn | E2: Churn Rate
A3: Intl Plan | B3: =COUNTIF(train!D2:D4251,"Yes") -> 396 | C3: =SUMIF(train!D2:D4251,"Yes",train!Q2:Q4251) -> 1774 | D3: =COUNTIFS(train!D2:D4251,"yes",train!T2:T4251,"No") -> 229 | E3: =D3/B3 -> 0.57828283
A4: Without Intl Plan | B4: =COUNTIF(train!D2:D4251,"No") -> 3854 | C4: =SUMIF(train!D2:D4251,"No",train!Q3:Q4252) -> 17030 | D4: =COUNTIFS(train!D2:D4251,"No",train!T2:T4251,"Yes") -> 431 | E4: =D4/B4 -> 0.11183186
